<?xml version="1.0" ?>
<robot name="abb_irb120" xmlns:xacro="http://ros.org/wiki/xacro">

<!--  <xacro:include filename="$(find robot_description)/urdf/common_colors.xacro"/> -->
  <xacro:include filename="$(find robot_description)/urdf/abb_common/common_materials.xacro"/>

  <xacro:abb_irb120 prefix=""/>

  <xacro:macro name="abb_irb120" params="prefix">

<!-- ros_control plugin -->
  <gazebo>
  <plugin name="gazebo_ros_control" filename="libgazebo_ros_control.so">
  <robotNamespace>/irb120</robotNamespace>
  <robotSimType>gazebo_ros_control/DefaultRobotHWSim</robotSimType>
  </plugin>
  </gazebo>


  <!-- Used for fixing robot to Gazebo 'base_link' -->
  <link name="world"/>
  <joint name="fixed" type="fixed">
  <parent link="world"/>
  <child link="base_link"/>
  <!-- this line is used to control the orgin of the base link -->
  <origin rpy="0 0 0" xyz="0 0 0"/>
  </joint>



  <!-- Description of base_link -->
  <link name="${prefix}base_link">

  <inertial>
  <mass value="6.215"/>
  <origin xyz="0 0 0" rpy="0 0 0"/>
  <inertia ixx="0.0247272" ixy="-8.0784E-05" ixz="0.00130902" iyy="0.0491285" iyz="-8.0419E-06" izz="0.0472376"/>
  </inertial>

  <visual>
  <origin xyz="0 0 0" rpy="0 0 0"/>
  <geometry>
  <mesh filename="package://robot_description/meshes/irb120/visual/base_link.stl"/>
  </geometry>
  <xacro:material_abb_orange />
  </visual>

  <collision>
  <origin xyz="0 0 0" rpy="0 0 0"/>
  <geometry>
  <mesh filename="package://robot_description/meshes/irb120/collision/base_link.stl"/>
  </geometry>
  <xacro:material_abb_yellow />
  </collision>

  </link>

  <!-- Joint - 1 -->
  <joint name="${prefix}joint_1" type="revolute">
  <origin rpy="0 0 0" xyz="0 0 0"/>
  <parent link="${prefix}base_link"/>
  <child link="${prefix}link_1"/>
  <limit effort="20" lower="-2.87979" upper="2.87979" velocity="4.36332"/>
  <axis xyz="0 0 1"/>
  <dynamics damping="1" friction="0"/>
  </joint>

  <!-- Description of link - 1 -->
  <link name="${prefix}link_1">

  <inertial>
  <mass value="3.067" />
  <origin xyz="0 0 0.23841" rpy="0 0 0"/>
  <inertia ixx="0.0142175" ixy="-1.28579E-05" ixz="-2.31364E-05" iyy="0.0144041" iyz="1.93404E-05" izz="0.0104533"/>
  </inertial>

  <visual>
  <origin xyz="0 0 0" rpy="0 0 0"/>
  <geometry>
  <mesh filename="package://robot_description/meshes/irb120/visual/link_1.stl"/>
  </geometry>
  <xacro:material_abb_orange />
  </visual>

  <collision>
  <origin xyz="0 0 0" rpy="0 0 0"/>
  <geometry>
  <mesh filename="package://robot_description/meshes/irb120/collision/link_1.stl"/>
  </geometry>
  <xacro:material_abb_yellow />
  </collision>

  </link>

  <!-- Joint - 2 -->
  <joint name="${prefix}joint_2" type="revolute">
  <origin rpy="0 0 0" xyz="0 0 0.29"/>
  <parent link="${prefix}link_1"/>
  <child link="${prefix}link_2"/>
  <limit effort="20" lower="-1.91986" upper="1.91986" velocity="4.36332"/>
  <axis xyz="0 -1 0"/>
  <dynamics damping="1" friction="0"/>
  </joint>

  <!-- Description of link - 2 -->
  <link name="${prefix}link_2">

  <inertial>
  <mass value="3.909"/>
  <origin xyz="0.00078 -0.00212 0.10124" rpy="0 0 0"/>
  <inertia ixx="0.0603111" ixy="9.83431E-06" ixz="5.72407E-05" iyy="0.041569" iyz="-0.00050497" izz="0.0259548"/>
  </inertial>

  <visual>
  <origin xyz="0 0 0" rpy="0 0 0"/>
  <geometry>
  <mesh filename="package://robot_description/meshes/irb120/visual/link_2.stl"/>
  </geometry>
  <xacro:material_abb_orange />
  </visual>

  <collision>
  <origin xyz="0 0 0" rpy="0 0 0"/>
  <geometry>
  <mesh filename="package://robot_description/meshes/irb120/collision/link_2.stl"/>
  </geometry>
  <xacro:material_abb_yellow />
  </collision>

  </link>

  <!-- Joint - 3 -->
  <joint name="${prefix}joint_3" type="revolute">
  <origin rpy="0 0 0" xyz="0 0 0.27"/>
  <parent link="${prefix}link_2"/>
  <child link="${prefix}link_3"/>
  <limit effort="20" lower="-1.91986" upper="1.22173" velocity="4.36332"/>
  <axis xyz="0 -1 0"/>
  <dynamics damping="1" friction="0.0"/>
  </joint>

  <!-- Description of link - 3 -->
  <link name="${prefix}link_3">

  <inertial>
  <mass value="2.944"/>
  <origin xyz="0.02281 0.00106 0.05791" rpy="0 0 0"/>
  <inertia ixx="0.00835606" ixy="-8.01545E-05" ixz="0.00142884" iyy="0.016713" iyz="-0.000182227" izz="0.0126984"/>
  </inertial>

  <visual>
  <origin xyz="0 0 0" rpy="0 0 0"/>
  <geometry>
  <mesh filename="package://robot_description/meshes/irb120/visual/link_3.stl"/>
  </geometry>
  <xacro:material_abb_orange />
  </visual>

  <collision>
  <origin xyz="0 0 0" rpy="0 0 0"/>
  <geometry>
  <mesh filename="package://robot_description/meshes/irb120/collision/link_3.stl"/>
  </geometry>
  <xacro:material_abb_yellow />
  </collision>

  </link>

  <!-- Joint - 4 -->
   <joint name="${prefix}joint_4" type="revolute">
   <origin rpy="0 0 0" xyz="0 0 0.07"/>
   <parent link="${prefix}link_3"/>
   <child link="${prefix}link_4"/>
   <limit effort="20" lower="-4" upper="4" velocity="5.58505"/>
   <axis xyz="1 0 0"/>
   <dynamics damping="1" friction="0"/>
   </joint>

  <!--  Description of link - 4 -->
  <link name="${prefix}link_4">

  <inertial>
  <mass value="0.1328"/>
  <origin xyz="0.2247 0.00015 0.00041" rpy="0 0 0"/>
  <inertia ixx="0.00284661" ixy="-2.12765E-05" ixz="-1.6435E-05" iyy="0.00401346" iyz="1.31336E-05" izz="0.0052535"/>
  </inertial>

  <visual>
  <origin xyz="0 0 0" rpy="0 0 0"/>
  <geometry>
  <mesh filename="package://robot_description/meshes/irb120/visual/link_4.stl"/>
  </geometry>
  <xacro:material_abb_orange />
  </visual>

  <collision>
  <origin xyz="0 0 0" rpy="0 0 0"/>
  <geometry>
  <mesh filename="package://robot_description/meshes/irb120/collision/link_4.stl"/>
  </geometry>
  <xacro:material_abb_yellow />
  </collision>

  </link>

  <!-- Joint - 5 -->
   <joint name="${prefix}joint_5" type="revolute">
   <origin rpy="0 0 0" xyz="0.302 0 0"/>
   <parent link="${prefix}link_4"/>
   <child link="${prefix}link_5"/>
   <limit effort="20" lower="-2.094395" upper="2.094395" velocity="5.58505"/>
   <axis xyz="0 -1 0"/>
   <dynamics damping="1" friction="0.0"/>
   </joint>

  <!-- Description of link - 5-->
  <link name="${prefix}link_5">

  <inertial>
  <mass value="0.546"/>
  <origin xyz="-0.00109 3.68E-05 6.22E-05" rpy="0 0 0"/>
  <inertia ixx="0.00284661" ixy="-2.12765E-05" ixz="-1.6435E-05" iyy="0.00401346" iyz="1.31336E-05" izz="0.0052535"/>
  </inertial>

  <visual>
  <origin xyz="0 0 0" rpy="0 0 0"/>
  <geometry>
  <mesh filename="package://robot_description/meshes/irb120/visual/link_5.stl"/>
  </geometry>
  <xacro:material_abb_orange />
  </visual>

  <collision>
  <origin xyz="0 0 0" rpy="0 0 0"/>
  <geometry>
  <mesh filename="package://robot_description/meshes/irb120/collision/link_5.stl"/>
  </geometry>
  <xacro:material_abb_yellow />
  </collision>

  </link>
  <!-- Joint - 6 -->
  <joint name="${prefix}joint_6" type="revolute">
  <origin rpy="0 0 0" xyz="0.072 0 0"/>
  <parent link="${prefix}link_5"/>
  <child link="${prefix}link_6"/>
  <limit effort="20" lower="-4" upper="4" velocity="7.33038"/>
  <axis xyz="1 0 0"/>
  <dynamics damping="1" friction="0.0"/>
  </joint>

  <!-- Description of link - 6 -->
  <link name="${prefix}link_6">

  <inertial>
  <mass value="0.137"/>
  <origin xyz="-0.00706 -0.00017 -1.32E-06" rpy="0 0 0"/>
   <inertia ixx="0.00284661" ixy="-2.12765E-05" ixz="-1.6435E-05" iyy="0.00401346" iyz="1.31336E-05" izz="0.0052535"/>
  </inertial>

  <visual>
  <origin xyz="0 0 0" rpy="0 0 0"/>
  <geometry>
  <mesh filename="package://robot_description/meshes/irb120/visual/link_6.stl"/>
  </geometry>
  <xacro:material_abb_black />
  </visual>

  <collision>
  <origin xyz="0 0 0" rpy="0 0 0"/>
  <geometry>
  <mesh filename="package://robot_description/meshes/irb120/collision/link_6.stl"/>
  </geometry>
  <xacro:material_abb_yellow />
  </collision>

  </link>

  <joint name="${prefix}sense_joint" type="fixed">
     <axis xyz="0 1 0" />
     <origin xyz="0 0 0" rpy="0 0 0"/>
     <parent link="${prefix}link_6"/>
     <child link="${prefix}sense_link"/>
   </joint>

   <link name="${prefix}sense_link">
     <collision>
       <origin xyz="0 0 0" rpy="0 0 0"/>
       <geometry>
         <box size="0.01 0.05 0.05"/>
       </geometry>
     </collision>

     <visual>
       <origin xyz="0 0 0" rpy="0 0 0"/>
       <geometry>
         <box size="0.01 0.05 0.05"/>
       </geometry>
       <material name="red"/>
     </visual>

     <inertial>
       <mass value="1e-5" />
       <origin xyz="0 0 0" rpy="0 0 0"/>
       <inertia ixx="1e-6" ixy="0" ixz="0" iyy="1e-6" iyz="0" izz="1e-6" />
     </inertial>
   </link>


  <transmission name="${prefix}tran1">
  <type>transmission_interface/SimpleTransmission</type>
  <joint name="${prefix}joint_1">
  <hardwareInterface>EffortJointInterface</hardwareInterface>
  </joint>
  <actuator name="motor1">
  <hardwareInterface>EffortJointInterface</hardwareInterface>
  <mechanicalReduction>1</mechanicalReduction>
  </actuator>
  </transmission>

  <transmission name="${prefix}tran2">
  <type>transmission_interface/SimpleTransmission</type>
  <joint name="${prefix}joint_2">
  <hardwareInterface>EffortJointInterface</hardwareInterface>
  </joint>
  <actuator name="motor2">
  <hardwareInterface>EffortJointInterface</hardwareInterface>
  <mechanicalReduction>1</mechanicalReduction>
  </actuator>
  </transmission>

  <transmission name="${prefix}tran3">
  <type>transmission_interface/SimpleTransmission</type>
  <joint name="${prefix}joint_3">
  <hardwareInterface>EffortJointInterface</hardwareInterface>
  </joint>
  <actuator name="motor3">
  <hardwareInterface>EffortJointInterface</hardwareInterface>
  <mechanicalReduction>1</mechanicalReduction>
  </actuator>
  </transmission>

  <transmission name="${prefix}tran4">
  <type>transmission_interface/SimpleTransmission</type>
  <joint name="${prefix}joint_4">
  <hardwareInterface>EffortJointInterface</hardwareInterface>
  </joint>
  <actuator name="motor4">
  <hardwareInterface>EffortJointInterface</hardwareInterface>
  <mechanicalReduction>1</mechanicalReduction>
  </actuator>
  </transmission>

  <transmission name="${prefix}tran5">
  <type>transmission_interface/SimpleTransmission</type>
  <joint name="${prefix}joint_5">
  <hardwareInterface>EffortJointInterface</hardwareInterface>
  </joint>
  <actuator name="motor5">
  <hardwareInterface>EffortJointInterface</hardwareInterface>
  <mechanicalReduction>1</mechanicalReduction>
  </actuator>
  </transmission>

  <transmission name="${prefix}tran6">
  <type>transmission_interface/SimpleTransmission</type>
  <joint name="${prefix}joint_6">
  <hardwareInterface>EffortJointInterface</hardwareInterface>
  </joint>
  <actuator name="motor6">
  <hardwareInterface>EffortJointInterface</hardwareInterface>
  <mechanicalReduction>1</mechanicalReduction>
  </actuator>
  </transmission>

<!-- Gazebo-specific link properties -->

  <gazebo reference="${prefix}base_link">
  <material>Gazebo/Orange</material>
  <turnGravityOff>true</turnGravityOff>
  </gazebo>

  <gazebo reference="${prefix}link_1">
  <material>Gazebo/Orange</material>
  <turnGravityOff>true</turnGravityOff>
  </gazebo>

  <gazebo reference="${prefix}link_2">
  <material>Gazebo/Orange</material>
  <turnGravityOff>true</turnGravityOff>
  </gazebo>

  <gazebo reference="${prefix}link_3">
  <material>Gazebo/Orange</material>
  <turnGravityOff>true</turnGravityOff>
  </gazebo>

  <gazebo reference="${prefix}link_4">
  <material>Gazebo/Orange</material>
  <turnGravityOff>true</turnGravityOff>
  </gazebo>

  <gazebo reference="${prefix}link_5">
  <material>Gazebo/Orange</material>
  <turnGravityOff>true</turnGravityOff>
  </gazebo>

  <gazebo reference="${prefix}link_6">
  <material>Gazebo/Black</material>
  <turnGravityOff>true</turnGravityOff>
  </gazebo>
  <gazebo reference="${prefix}sense_link">
  <material>Gazebo/Black</material>
  <turnGravityOff>true</turnGravityOff>
  </gazebo>

  <!-- <gazebo reference="${prefix}sense_link">
  <turnGravityOff>true</turnGravityOff>
  <provideFeedback>true</provideFeedback>
  <sensor name='my_contact' type='contact'>
     <contact>
       <collision>sense_link_collision</collision>
     </contact>
   </sensor>
</gazebo> -->
  <gazebo reference="${prefix}sense_joint">
    <provideFeedback>true</provideFeedback>
  </gazebo>
  <gazebo reference="${prefix}joint_6">
    <provideFeedback>true</provideFeedback>
  </gazebo>


  <!-- <gazebo  reference="sense_link">
  <sensor name="sense_link_contact_sensor" type="contact">
    <always_on>1</always_on>
    <update_rate>30</update_rate>
    <geom>sense_link_geom</geom>
    <contact>
      <collision>sense_link_collision</collision>
    </contact>
    <plugin name="sense_link_bumper" filename="libgazebo_ros_bumper.so">
      <bumperTopicName>/force_sensor</bumperTopicName>
      <frameName>world</frameName>
    </plugin>
  </sensor>
 </gazebo> -->

 <!-- <gazebo reference="sense_link">
   <sensor name='my_contact' type='contact'>
      <contact>
        <collision>sense_link_collision</collision>
      </contact>
    </sensor>
    <plugin name="sense_gazebo_ros_bumper_controller" filename="libgazebo_ros_bumper.so">
      <alwaysOn>true</alwaysOn>
      <updateRate>10</updateRate>
      <bumperTopicName>/sense_bumper</bumperTopicName>
      <frameName>sense_link</frameName>
    </plugin>
 </gazebo> -->


 <!-- The ft_sensor plugin -->
 <gazebo>
     <plugin name="ft_sensor" filename="libgazebo_ros_ft_sensor.so">
         <updateRate>500.0</updateRate>
         <topicName>ft_sensor_topic</topicName>
         <jointName>${prefix}joint_6</jointName>
         <always_on>1</always_on>
     </plugin>
 </gazebo>

 <gazebo reference="${prefix}sense_link">
   <sensor name='my_contact' type='contact'>
      <contact>
        <collision>sense_link_collision</collision>
      </contact>
  <plugin name="${prefix}sense_link_bumper" filename="libgazebo_ros_bumper.so">
    <alwaysOn>true</alwaysOn>
    <updateRate>100.0</updateRate>
    <bumperTopicName>/irb120/force_feedback</bumperTopicName>
    <!-- <topicName>bumper_sensor_topic</topicName> -->
    <frameName>world</frameName>
  </plugin>
</sensor>
</gazebo>


  <!-- <gazebo reference="sense_joint">
    <provideFeedback>true</provideFeedback>
    <plugin name="sense_joint_ft_sensor" filename="libgazebo_ros_ft_sensor.so">
      <always_on>1</always_on>
        <updateRate>10.0</updateRate>
        <topicName>/ft_sensor_topic</topicName>
        <jointName>sense_joint</jointName>
    </plugin>
</gazebo> -->


  <!-- <gazebo reference="sense_joint">
    <sensor name="sense_joint_contact" type="force_torque">
      <always_on>1</always_on>
      <update_rate>10</update_rate>
      <topic>/gazebo/sensor</topic>
      <frame>sense_link</frame>
      <plugin name="sense_joint_ft_sensor" filename="libgazebo_ros_ft_sensor.so"/>
    </sensor>
  </gazebo> -->

</xacro:macro>

</robot>
